ERROR:root:Error:
Traceback (most recent call last):
  File "pymssql.pyx", line 447, in pymssql.Cursor.execute (pymssql.c:6867)
  File "_mssql.pyx", line 998, in _mssql.MSSQLConnection.execute_query (_mssql.c:10765)
  File "_mssql.pyx", line 1029, in _mssql.MSSQLConnection.execute_query (_mssql.c:10639)
  File "_mssql.pyx", line 1162, in _mssql.MSSQLConnection.format_and_run_query (_mssql.c:11894)
  File "_mssql.pyx", line 1568, in _mssql.check_cancel_and_raise (_mssql.c:15788)
  File "_mssql.pyx", line 1612, in _mssql.maybe_raise_MSSQLDatabaseException (_mssql.c:16426)
_mssql.MSSQLDatabaseException: (2627, b"Violation of PRIMARY KEY constraint 'c_VoucherHead_pk'. Cannot insert duplicate key in object 'dbo.c_VoucherHead'.DB-Lib error message 20018, severity 14:\nGeneral SQL Server error: Check messages from the SQL Server\n")

During handling of the above exception, another exception occurred:

Traceback (most recent call last):
  File "C:\Python34\lib\site-packages\sqlalchemy\engine\base.py", line 1139, in _execute_context
    context)
  File "C:\Python34\lib\site-packages\sqlalchemy\engine\default.py", line 450, in do_execute
    cursor.execute(statement, parameters)
  File "pymssql.pyx", line 464, in pymssql.Cursor.execute (pymssql.c:7170)
pymssql.IntegrityError: (2627, b"Violation of PRIMARY KEY constraint 'c_VoucherHead_pk'. Cannot insert duplicate key in object 'dbo.c_VoucherHead'.DB-Lib error message 20018, severity 14:\nGeneral SQL Server error: Check messages from the SQL Server\n")

The above exception was the direct cause of the following exception:

Traceback (most recent call last):
  File "D:/sync/Projects/pycharmProjects/HBS/new_main.py", line 131, in <module>
    insert_interface()
  File "D:/sync/Projects/pycharmProjects/HBS/new_main.py", line 42, in insert_interface
    Inter_Session.commit()
  File "C:\Python34\lib\site-packages\sqlalchemy\orm\session.py", line 790, in commit
    self.transaction.commit()
  File "C:\Python34\lib\site-packages\sqlalchemy\orm\session.py", line 392, in commit
    self._prepare_impl()
  File "C:\Python34\lib\site-packages\sqlalchemy\orm\session.py", line 372, in _prepare_impl
    self.session.flush()
  File "C:\Python34\lib\site-packages\sqlalchemy\orm\session.py", line 2004, in flush
    self._flush(objects)
  File "C:\Python34\lib\site-packages\sqlalchemy\orm\session.py", line 2122, in _flush
    transaction.rollback(_capture_exception=True)
  File "C:\Python34\lib\site-packages\sqlalchemy\util\langhelpers.py", line 60, in __exit__
    compat.reraise(exc_type, exc_value, exc_tb)
  File "C:\Python34\lib\site-packages\sqlalchemy\util\compat.py", line 182, in reraise
    raise value
  File "C:\Python34\lib\site-packages\sqlalchemy\orm\session.py", line 2086, in _flush
    flush_context.execute()
  File "C:\Python34\lib\site-packages\sqlalchemy\orm\unitofwork.py", line 373, in execute
    rec.execute(self)
  File "C:\Python34\lib\site-packages\sqlalchemy\orm\unitofwork.py", line 532, in execute
    uow
  File "C:\Python34\lib\site-packages\sqlalchemy\orm\persistence.py", line 174, in save_obj
    mapper, table, insert)
  File "C:\Python34\lib\site-packages\sqlalchemy\orm\persistence.py", line 748, in _emit_insert_statements
    execute(statement, multiparams)
  File "C:\Python34\lib\site-packages\sqlalchemy\engine\base.py", line 914, in execute
    return meth(self, multiparams, params)
  File "C:\Python34\lib\site-packages\sqlalchemy\sql\elements.py", line 323, in _execute_on_connection
    return connection._execute_clauseelement(self, multiparams, params)
  File "C:\Python34\lib\site-packages\sqlalchemy\engine\base.py", line 1010, in _execute_clauseelement
    compiled_sql, distilled_params
  File "C:\Python34\lib\site-packages\sqlalchemy\engine\base.py", line 1146, in _execute_context
    context)
  File "C:\Python34\lib\site-packages\sqlalchemy\engine\base.py", line 1341, in _handle_dbapi_exception
    exc_info
  File "C:\Python34\lib\site-packages\sqlalchemy\util\compat.py", line 188, in raise_from_cause
    reraise(type(exception), exception, tb=exc_tb, cause=exc_value)
  File "C:\Python34\lib\site-packages\sqlalchemy\util\compat.py", line 181, in reraise
    raise value.with_traceback(tb)
  File "C:\Python34\lib\site-packages\sqlalchemy\engine\base.py", line 1139, in _execute_context
    context)
  File "C:\Python34\lib\site-packages\sqlalchemy\engine\default.py", line 450, in do_execute
    cursor.execute(statement, parameters)
  File "pymssql.pyx", line 464, in pymssql.Cursor.execute (pymssql.c:7170)
sqlalchemy.exc.IntegrityError: (pymssql.IntegrityError) (2627, b"Violation of PRIMARY KEY constraint 'c_VoucherHead_pk'. Cannot insert duplicate key in object 'dbo.c_VoucherHead'.DB-Lib error message 20018, severity 14:\nGeneral SQL Server error: Check messages from the SQL Server\n") [SQL: 'INSERT INTO [c_VoucherHead] (account_book, jde_number, line_count, year, period, total_amount, voucher_date, voucher_category, preparer, create_date) VALUES (%(account_book)s, %(jde_number)s, %(line_count)s, %(year)s, %(period)s, %(total_amount)s, %(voucher_date)s, %(voucher_category)s, %(preparer)s, %(create_date)s)'] [parameters: {'voucher_category': 'transfer', 'preparer': 'morningstar', 'total_amount': 336.0, 'account_book': '01046', 'year': 2015, 'line_count': 2, 'jde_number': '15081912', 'period': 8, 'voucher_date': datetime.datetime(2015, 8, 19, 0, 0), 'create_date': datetime.datetime(2015, 9, 22, 11, 2, 53, 759003)}]
------------------------

2015-09-22 11:02:59.136538
开始向接口表插入数据
接口会计期间为2015年7月
接口表清除完毕
------------------------

2015-09-22 11:03:50.111920
开始向接口表插入数据
接口会计期间为2015年8月
接口表清除完毕
接口表导入完成
开始对账套R_DH_TJ_0919导入凭证账套R_DH_TJ_0919的当前会计期间为2015年8月凭证删除完毕账套R_DH_TJ_0919的凭证导入完成ERROR:root:Error:
Traceback (most recent call last):
  File "D:/sync/Projects/pycharmProjects/HBS/new_main.py", line 132, in <module>
    insert_interface()
  File "D:/sync/Projects/pycharmProjects/HBS/new_main.py", line 20, in insert_interface
    voucher_head, voucher_body = voucher_info()
TypeError: 'int' object is not iterable
ERROR:root:Error:
Traceback (most recent call last):
  File "D:/sync/Projects/pycharmProjects/HBS/new_main.py", line 132, in <module>
    insert_interface()
  File "D:/sync/Projects/pycharmProjects/HBS/new_main.py", line 20, in insert_interface
    voucher_head, voucher_body = voucher_info()
TypeError: 'int' object is not iterable
****************************************

2015-09-22 11:43:14.039815
开始向接口表插入数据
接口会计期间为2015年8月
接口表清除完毕
接口表导入完成
ERROR:root:Error:
Traceback (most recent call last):
  File "pymssql.pyx", line 447, in pymssql.Cursor.execute (pymssql.c:6867)
  File "_mssql.pyx", line 998, in _mssql.MSSQLConnection.execute_query (_mssql.c:10765)
  File "_mssql.pyx", line 1029, in _mssql.MSSQLConnection.execute_query (_mssql.c:10639)
  File "_mssql.pyx", line 1162, in _mssql.MSSQLConnection.format_and_run_query (_mssql.c:11894)
  File "_mssql.pyx", line 1568, in _mssql.check_cancel_and_raise (_mssql.c:15788)
  File "_mssql.pyx", line 1612, in _mssql.maybe_raise_MSSQLDatabaseException (_mssql.c:16426)
_mssql.MSSQLDatabaseException: (547, b'The DELETE statement conflicted with the REFERENCE constraint "FK__c_VoucherBody__7422149C". The conflict occurred in database "R_DH_DI_0921", table "dbo.c_VoucherBody".DB-Lib error message 20018, severity 16:\nGeneral SQL Server error: Check messages from the SQL Server\n')

During handling of the above exception, another exception occurred:

Traceback (most recent call last):
  File "C:\Python34\lib\site-packages\sqlalchemy\engine\base.py", line 1139, in _execute_context
    context)
  File "C:\Python34\lib\site-packages\sqlalchemy\engine\default.py", line 450, in do_execute
    cursor.execute(statement, parameters)
  File "pymssql.pyx", line 464, in pymssql.Cursor.execute (pymssql.c:7170)
pymssql.IntegrityError: (547, b'The DELETE statement conflicted with the REFERENCE constraint "FK__c_VoucherBody__7422149C". The conflict occurred in database "R_DH_DI_0921", table "dbo.c_VoucherBody".DB-Lib error message 20018, severity 16:\nGeneral SQL Server error: Check messages from the SQL Server\n')

The above exception was the direct cause of the following exception:

Traceback (most recent call last):
  File "D:/sync/Projects/pycharmProjects/HBS/main.py", line 134, in <module>
    result = insert_interface()
  File "D:/sync/Projects/pycharmProjects/HBS/main.py", line 36, in insert_interface
    synchronize_session=False)
  File "C:\Python34\lib\site-packages\sqlalchemy\orm\query.py", line 2828, in delete
    delete_op.exec_()
  File "C:\Python34\lib\site-packages\sqlalchemy\orm\persistence.py", line 1106, in exec_
    self._do_exec()
  File "C:\Python34\lib\site-packages\sqlalchemy\orm\persistence.py", line 1284, in _do_exec
    mapper=self.mapper)
  File "C:\Python34\lib\site-packages\sqlalchemy\orm\session.py", line 1023, in execute
    bind, close_with_result=True).execute(clause, params or {})
  File "C:\Python34\lib\site-packages\sqlalchemy\engine\base.py", line 914, in execute
    return meth(self, multiparams, params)
  File "C:\Python34\lib\site-packages\sqlalchemy\sql\elements.py", line 323, in _execute_on_connection
    return connection._execute_clauseelement(self, multiparams, params)
  File "C:\Python34\lib\site-packages\sqlalchemy\engine\base.py", line 1010, in _execute_clauseelement
    compiled_sql, distilled_params
  File "C:\Python34\lib\site-packages\sqlalchemy\engine\base.py", line 1146, in _execute_context
    context)
  File "C:\Python34\lib\site-packages\sqlalchemy\engine\base.py", line 1341, in _handle_dbapi_exception
    exc_info
  File "C:\Python34\lib\site-packages\sqlalchemy\util\compat.py", line 188, in raise_from_cause
    reraise(type(exception), exception, tb=exc_tb, cause=exc_value)
  File "C:\Python34\lib\site-packages\sqlalchemy\util\compat.py", line 181, in reraise
    raise value.with_traceback(tb)
  File "C:\Python34\lib\site-packages\sqlalchemy\engine\base.py", line 1139, in _execute_context
    context)
  File "C:\Python34\lib\site-packages\sqlalchemy\engine\default.py", line 450, in do_execute
    cursor.execute(statement, parameters)
  File "pymssql.pyx", line 464, in pymssql.Cursor.execute (pymssql.c:7170)
sqlalchemy.exc.IntegrityError: (pymssql.IntegrityError) (547, b'The DELETE statement conflicted with the REFERENCE constraint "FK__c_VoucherBody__7422149C". The conflict occurred in database "R_DH_DI_0921", table "dbo.c_VoucherBody".DB-Lib error message 20018, severity 16:\nGeneral SQL Server error: Check messages from the SQL Server\n') [SQL: 'DELETE FROM [c_VoucherHead] WHERE [c_VoucherHead].year = %(year_1)s AND [c_VoucherHead].period = %(period_1)s'] [parameters: {'period_1': 8, 'year_1': 2015}]
****************************************

2015-09-22 13:07:39.053622
开始向接口表插入数据
接口会计期间为2015年8月
****************************************

2015-09-22 13:06:10.582778
开始向接口表插入数据
接口会计期间为2015年8月
接口表清除完毕
接口表导入完成, 共导入数据1743行
--------------------
开始对账套R_DH_DI_0921导入凭证
账套R_DH_DI_0921的当前会计期间为2015年8月
凭证删除完毕账套R_DH_DI_0921的凭证导入完成--------------------
开始对账套R_DH_TJ_0919导入凭证
账套R_DH_TJ_0919的当前会计期间为2015年8月
凭证删除完毕账套R_DH_TJ_0919的凭证导入完成
****************************************

2015-09-22 14:51:52.556300
开始向接口表插入数据
接口会计期间为2015年8月
接口表清除完毕
接口表导入完成, 共导入数据12行
--------------------
开始对账套R_DH_DI_0921导入凭证
账套R_DH_DI_0921的当前会计期间为2015年8月
凭证删除完毕
账套R_DH_DI_0921的凭证导入完成
--------------------
开始对账套R_DH_TJ_0919导入凭证
账套R_DH_TJ_0919的当前会计期间为2015年8月
凭证删除完毕
账套R_DH_TJ_0919的凭证导入完成

****************************************

2015-09-23 15:53:52.328125
开始向接口表插入数据
接口会计期间为2015年8月
接口表清除完毕
接口表导入完成, 共导入数据12行
--------------------
开始对账套R_DH_DI_0921导入凭证
账套R_DH_DI_0921的当前会计期间为2015年8月
凭证删除完毕
账套R_DH_DI_0921的凭证导入完成
--------------------
开始对账套R_DH_TJ_0919导入凭证
账套R_DH_TJ_0919的当前会计期间为2015年8月
凭证删除完毕
账套R_DH_TJ_0919的凭证导入完成

****************************************

2015-09-23 15:55:03.948480
开始向接口表插入数据
接口会计期间为2015年8月
接口表清除完毕
接口表导入完成, 共导入数据12行
--------------------
开始对账套R_DH_DI_0921导入凭证
账套R_DH_DI_0921的当前会计期间为2015年8月
凭证删除完毕
账套R_DH_DI_0921的凭证导入完成
--------------------
开始对账套R_DH_TJ_0919导入凭证
账套R_DH_TJ_0919的当前会计期间为2015年8月
凭证删除完毕
账套R_DH_TJ_0919的凭证导入完成

****************************************

2015-09-23 15:59:12.915099
开始向接口表插入数据
接口会计期间为2015年8月
接口表清除完毕
接口表导入完成, 共导入数据1783行
--------------------
开始对账套R_DH_DI_0921导入凭证
账套R_DH_DI_0921的当前会计期间为2015年8月
凭证删除完毕
账套R_DH_DI_0921的凭证导入完成
--------------------
开始对账套R_DH_TJ_0919导入凭证
账套R_DH_TJ_0919的当前会计期间为2015年8月
凭证删除完毕
账套R_DH_TJ_0919的凭证导入完成

****************************************

2015-09-23 16:51:51.493269
开始向接口表插入数据
接口会计期间为2015年8月
接口表清除完毕
接口表导入完成, 共导入数据12行
--------------------
开始对账套R_DH_DI_0921导入凭证
账套R_DH_DI_0921的当前会计期间为2015年8月
凭证删除完毕
账套R_DH_DI_0921的凭证导入完成
--------------------
开始对账套R_DH_TJ_0919导入凭证
账套R_DH_TJ_0919的当前会计期间为2015年8月
凭证删除完毕
账套R_DH_TJ_0919的凭证导入完成

****************************************

2015-09-23 16:53:40.914390
开始向接口表插入数据
接口会计期间为2015年8月
接口表清除完毕
接口表导入完成, 共导入数据12行
--------------------
开始对账套R_DH_DI_0921导入凭证
账套R_DH_DI_0921的当前会计期间为2015年8月
凭证删除完毕
账套R_DH_DI_0921的凭证导入完成
--------------------
开始对账套R_DH_TJ_0919导入凭证
账套R_DH_TJ_0919的当前会计期间为2015年8月
凭证删除完毕
账套R_DH_TJ_0919的凭证导入完成

****************************************

2015-09-23 17:34:08.274711
开始向接口表插入数据
接口会计期间为2015年8月
接口表清除完毕
接口表导入完成, 共导入数据53行
ERROR:root:Error:
Traceback (most recent call last):
  File "D:/sync/Projects/pycharmProjects/HBS/main.py", line 138, in <module>
    interface_to_kingdee(DB_DI, DI_CODE)
  File "D:/sync/Projects/pycharmProjects/HBS/main.py", line 130, in interface_to_kingdee
    fp.write("账套" + database + "的凭证导入完成\n" + "共导入凭证" + str(len(voucher_head)) + "张")
TypeError: object of type 'Query' has no len()
--------------------
开始对账套R_DH_DI_0921导入凭证
账套R_DH_DI_0921的当前会计期间为2015年8月
凭证删除完毕

****************************************

2015-09-23 17:35:05.785458
开始向接口表插入数据
接口会计期间为2015年8月
接口表清除完毕
接口表导入完成, 共导入数据53行
--------------------
开始对账套R_DH_DI_0921导入凭证
账套R_DH_DI_0921的当前会计期间为2015年8月
凭证删除完毕
账套R_DH_DI_0921的凭证导入完成
共导入凭证1张--------------------
开始对账套R_DH_TJ_0919导入凭证
账套R_DH_TJ_0919的当前会计期间为2015年8月
凭证删除完毕
账套R_DH_TJ_0919的凭证导入完成
共导入凭证13张
****************************************

2015-09-23 17:35:52.327640
开始向接口表插入数据
接口会计期间为2015年8月
接口表清除完毕
接口表导入完成, 共导入数据7704行
--------------------
开始对账套R_DH_DI_0921导入凭证
账套R_DH_DI_0921的当前会计期间为2015年8月
凭证删除完毕
账套R_DH_DI_0921的凭证导入完成,共导入凭证1732张
--------------------
开始对账套R_DH_TJ_0919导入凭证
账套R_DH_TJ_0919的当前会计期间为2015年8月
凭证删除完毕
账套R_DH_TJ_0919的凭证导入完成,共导入凭证13张

****************************************

2015-10-08 15:02:33.281071
开始向接口表插入数据
接口会计期间为2015年9月
接口表清除完毕
接口表导入完成, 共导入数据9181行
ERROR:root:Error:
Traceback (most recent call last):
  File "D:/sync/Projects/pycharmProjects/HBS/main.py", line 138, in <module>
    interface_to_kingdee(DB_DI, DI_CODE)
  File "D:/sync/Projects/pycharmProjects/HBS/main.py", line 117, in interface_to_kingdee
    account_id = session.query(MatchTable.F_101).filter(MatchTable.FNumber == each_line.jde_account).first()[0]
TypeError: 'NoneType' object is not subscriptable
--------------------
开始对账套DH_DI导入凭证
账套DH_DI的当前会计期间为2015年9月
凭证删除完毕

****************************************

2015-10-08 16:03:14.630843
开始向接口表插入数据
接口会计期间为2015年9月
接口表清除完毕
接口表导入完成, 共导入数据9181行
